Workbook

Sheet 资产盘点明细
A1: 序号 | B1: 分公司 | C1: 资产编号 | D1: 分公司编号 | E1: 资产类目 | F1: 电脑序列号 | G1: 供应商 | H1: 物品分类 | I1: 资产名称 | J1: 图片 | K1: 入库日期 | L1: 是否租用 | M1: 数量 | N1: 规格 | O1: 单价 | P1: 购入金额 | Q1: 出库日期 | R1: 所属部门 | S1: 使用人 | T1: 当前状态 | U1: 警戒线 | V1: 是否充足 | W1: 备注
A2: 1 | B2: 赣州分公司 | C2: =IF(B2="","",_xlfn.XLOOKUP(I2,资产分类大全!C:C,资产分类大全!D:D)) -> A-c00006 | E2: 固定资产类 | G2: 鸿励 | H2: 电子设备 | I2: 沙发 | K2: 45954 | L2: 自购 | M2: 2 | O2: =IF(M2="","",P2/M2) -> 100 | P2: 200 | Q2: 45954 | R2: 总经办 | S2: / | T2: 使用中 | U2: =IF(M2="","",_xlfn.XLOOKUP(I2,资产分类大全!C:C,资产分类大全!F:F,0)) -> 1 | V2: =IF(I2<>"",IF(M2<U2,"不足","充足"),"") -> 充足
A3: =IF(B3="","",ROW()-1) -> 2 | B3: 5分 | C3: =IF(B3="","",_xlfn.XLOOKUP(I3,资产分类大全!C:C,资产分类大全!D:D)) -> 0 | E3: 固定资产类 | H3: 办公设备 | O3: =IF(M3="","",P3/M3) | R3: 总经办 | S3: / | U3: =IF(M3="","",_xlfn.XLOOKUP(I3,资产分类大全!C:C,资产分类大全!F:F,0)) | V3: =IF(I3<>"",IF(M3<U3,"不足","充足"),"")
A4: =IF(B4="","",ROW()-1) -> 3 | B4: 徐州分公司 | C4: =IF(B4="","",_xlfn.XLOOKUP(I4,资产分类大全!C:C,资产分类大全!D:D)) -> 0 | O4: =IF(M4="","",P4/M4) | U4: =IF(M4="","",_xlfn.XLOOKUP(I4,资产分类大全!C:C,资产分类大全!F:F,0)) | V4: =IF(I4<>"",IF(M4<U4,"不足","充足"),"")
A5: =IF(B5="","",ROW()-1) -> 4 | B5: 5分 | C5: =IF(B5="","",_xlfn.XLOOKUP(I5,资产分类大全!C:C,资产分类大全!D:D)) -> B-c00006 | E5: 低值易耗品类 | H5: 清洁用品 | I5: 垃圾袋 | K5: 45910 | M5: 10 | O5: =IF(M5="","",P5/M5) -> 0 | U5: =IF(M5="","",_xlfn.XLOOKUP(I5,资产分类大全!C:C,资产分类大全!F:F,0)) -> 30 | V5: =IF(I5<>"",IF(M5<U5,"不足","充足"),"") -> 不足
A6: =IF(B6="","",ROW()-1) -> 5 | B6: 2分 | C6: =IF(B6="","",_xlfn.XLOOKUP(I6,资产分类大全!C:C,资产分类大全!D:D)) -> 0 | O6: =IF(M6="","",P6/M6) | U6: =IF(M6="","",_xlfn.XLOOKUP(I6,资产分类大全!C:C,资产分类大全!F:F,0)) | V6: =IF(I6<>"",IF(M6<U6,"不足","充足"),"")
A7: =IF(B7="","",ROW()-1) | C7: =IF(B7="","",_xlfn.XLOOKUP(I7,资产分类大全!C:C,资产分类大全!D:D)) | O7: =IF(M7="","",P7/M7) | U7: =IF(M7="","",_xlfn.XLOOKUP(I7,资产分类大全!C:C,资产分类大全!F:F,0)) | V7: =IF(I7<>"",IF(M7<U7,"不足","充足"),"")
A8: =IF(B8="","",ROW()-1) | C8: =IF(B8="","",_xlfn.XLOOKUP(I8,资产分类大全!C:C,资产分类大全!D:D)) | O8: =IF(M8="","",P8/M8) | U8: =IF(M8="","",_xlfn.XLOOKUP(I8,资产分类大全!C:C,资产分类大全!F:F,0)) | V8: =IF(I8<>"",IF(M8<U8,"不足","充足"),"")
A9: =IF(B9="","",ROW()-1) | C9: =IF(B9="","",_xlfn.XLOOKUP(I9,资产分类大全!C:C,资产分类大全!D:D)) | O9: =IF(M9="","",P9/M9) | U9: =IF(M9="","",_xlfn.XLOOKUP(I9,资产分类大全!C:C,资产分类大全!F:F,0)) | V9: =IF(I9<>"",IF(M9<U9,"不足","充足"),"")
A10: =IF(B10="","",ROW()-1) | C10: =IF(B10="","",_xlfn.XLOOKUP(I10,资产分类大全!C:C,资产分类大全!D:D)) | O10: =IF(M10="","",P10/M10) | U10: =IF(M10="","",_xlfn.XLOOKUP(I10,资产分类大全!C:C,资产分类大全!F:F,0)) | V10: =IF(I10<>"",IF(M10<U10,"不足","充足"),"")
A11: =IF(B11="","",ROW()-1) | C11: =IF(B11="","",_xlfn.XLOOKUP(I11,资产分类大全!C:C,资产分类大全!D:D)) | O11: =IF(M11="","",P11/M11) | U11: =IF(M11="","",_xlfn.XLOOKUP(I11,资产分类大全!C:C,资产分类大全!F:F,0)) | V11: =IF(I11<>"",IF(M11<U11,"不足","充足"),"")
A12: =IF(B12="","",ROW()-1) | C12: =IF(B12="","",_xlfn.XLOOKUP(I12,资产分类大全!C:C,资产分类大全!D:D)) | O12: =IF(M12="","",P12/M12) | U12: =IF(M12="","",_xlfn.XLOOKUP(I12,资产分类大全!C:C,资产分类大全!F:F,0)) | V12: =IF(I12<>"",IF(M12<U12,"不足","充足"),"")
A13: =IF(B13="","",ROW()-1) | C13: =IF(B13="","",_xlfn.XLOOKUP(I13,资产分类大全!C:C,资产分类大全!D:D)) | O13: =IF(M13="","",P13/M13) | U13: =IF(M13="","",_xlfn.XLOOKUP(I13,资产分类大全!C:C,资产分类大全!F:F,0)) | V13: =IF(I13<>"",IF(M13<U13,"不足","充足"),"")
A14: =IF(B14="","",ROW()-1) | C14: =IF(B14="","",_xlfn.XLOOKUP(I14,资产分类大全!C:C,资产分类大全!D:D)) | O14: =IF(M14="","",P14/M14) | U14: =IF(M14="","",_xlfn.XLOOKUP(I14,资产分类大全!C:C,资产分类大全!F:F,0)) | V14: =IF(I14<>"",IF(M14<U14,"不足","充足"),"")
A15: =IF(B15="","",ROW()-1) | C15: =IF(B15="","",_xlfn.XLOOKUP(I15,资产分类大全!C:C,资产分类大全!D:D)) | O15: =IF(M15="","",P15/M15) | U15: =IF(M15="","",_xlfn.XLOOKUP(I15,资产分类大全!C:C,资产分类大全!F:F,0)) | V15: =IF(I15<>"",IF(M15<U15,"不足","充足"),"")
A16: =IF(B16="","",ROW()-1) | C16: =IF(B16="","",_xlfn.XLOOKUP(I16,资产分类大全!C:C,资产分类大全!D:D)) | O16: =IF(M16="","",P16/M16) | U16: =IF(M16="","",_xlfn.XLOOKUP(I16,资产分类大全!C:C,资产分类大全!F:F,0)) | V16: =IF(I16<>"",IF(M16<U16,"不足","充足"),"")
A17: =IF(B17="","",ROW()-1) | C17: =IF(B17="","",_xlfn.XLOOKUP(I17,资产分类大全!C:C,资产分类大全!D:D)) | O17: =IF(M17="","",P17/M17) | U17: =IF(M17="","",_xlfn.XLOOKUP(I17,资产分类大全!C:C,资产分类大全!F:F,0)) | V17: =IF(I17<>"",IF(M17<U17,"不足","充足"),"")
A18: =IF(B18="","",ROW()-1) | C18: =IF(B18="","",_xlfn.XLOOKUP(I18,资产分类大全!C:C,资产分类大全!D:D)) | O18: =IF(M18="","",P18/M18) | U18: =IF(M18="","",_xlfn.XLOOKUP(I18,资产分类大全!C:C,资产分类大全!F:F,0)) | V18: =IF(I18<>"",IF(M18<U18,"不足","充足"),"")
... A23: =IF(B23="","",ROW()-1) | C23: =IF(B23="","",_xlfn.XLOOKUP(I23,资产分类大全!C:C,资产分类大全!D:D)) | O23: =IF(M23="","",P23/M23) | U23: =IF(M23="","",_xlfn.XLOOKUP(I23,资产分类大全!C:C,资产分类大全!F:F,0)) | V23: =IF(I23<>"",IF(M23<U23,"不足","充足"),"")
A24: =IF(B24="","",ROW()-1) | C24: =IF(B24="","",_xlfn.XLOOKUP(I24,资产分类大全!C:C,资产分类大全!D:D)) | E24: 固定资产类 | H24: 办公设备 | I24: 电脑（一体机） | O24: =IF(M24="","",P24/M24) | U24: =IF(M24="","",_xlfn.XLOOKUP(I24,资产分类大全!C:C,资产分类大全!F:F,0)) | V24: =IF(I24<>"",IF(M24<U24,"不足","充足"),"") -> 充足
A25: =IF(B25="","",ROW()-1) | C25: =IF(B25="","",_xlfn.XLOOKUP(I25,资产分类大全!C:C,资产分类大全!D:D)) | O25: =IF(M25="","",P25/M25) | U25: =IF(M25="","",_xlfn.XLOOKUP(I25,资产分类大全!C:C,资产分类大全!F:F,0)) | V25: =IF(I25<>"",IF(M25<U25,"不足","充足"),"")
A26: =IF(B26="","",ROW()-1) | C26: =IF(B26="","",_xlfn.XLOOKUP(I26,资产分类大全!C:C,资产分类大全!D:D)) | O26: =IF(M26="","",P26/M26) | U26: =IF(M26="","",_xlfn.XLOOKUP(I26,资产分类大全!C:C,资产分类大全!F:F,0)) | V26: =IF(I26<>"",IF(M26<U26,"不足","充足"),"")
A27: =IF(B27="","",ROW()-1) | C27: =IF(B27="","",_xlfn.XLOOKUP(I27,资产分类大全!C:C,资产分类大全!D:D)) | O27: =IF(M27="","",P27/M27) | U27: =IF(M27="","",_xlfn.XLOOKUP(I27,资产分类大全!C:C,资产分类大全!F:F,0)) | V27: =IF(I27<>"",IF(M27<U27,"不足","充足"),"")
A28: =IF(B28="","",ROW()-1) | C28: =IF(B28="","",_xlfn.XLOOKUP(I28,资产分类大全!C:C,资产分类大全!D:D)) | O28: =IF(M28="","",P28/M28) | U28: =IF(M28="","",_xlfn.XLOOKUP(I28,资产分类大全!C:C,资产分类大全!F:F,0)) | V28: =IF(I28<>"",IF(M28<U28,"不足","充足"),"")
A29: =IF(B29="","",ROW()-1) | C29: =IF(B29="","",_xlfn.XLOOKUP(I29,资产分类大全!C:C,资产分类大全!D:D)) | O29: =IF(M29="","",P29/M29) | U29: =IF(M29="","",_xlfn.XLOOKUP(I29,资产分类大全!C:C,资产分类大全!F:F,0)) | V29: =IF(I29<>"",IF(M29<U29,"不足","充足"),"")
A30: =IF(B30="","",ROW()-1) | C30: =IF(B30="","",_xlfn.XLOOKUP(I30,资产分类大全!C:C,资产分类大全!D:D)) | O30: =IF(M30="","",P30/M30) | U30: =IF(M30="","",_xlfn.XLOOKUP(I30,资产分类大全!C:C,资产分类大全!F:F,0)) | V30: =IF(I30<>"",IF(M30<U30,"不足","充足"),"")
A31: =IF(B31="","",ROW()-1) | C31: =IF(B31="","",_xlfn.XLOOKUP(I31,资产分类大全!C:C,资产分类大全!D:D)) | O31: =IF(M31="","",P31/M31) | U31: =IF(M31="","",_xlfn.XLOOKUP(I31,资产分类大全!C:C,资产分类大全!F:F,0)) | V31: =IF(I31<>"",IF(M31<U31,"不足","充足"),"")
A32: =IF(B32="","",ROW()-1) | C32: =IF(B32="","",_xlfn.XLOOKUP(I32,资产分类大全!C:C,资产分类大全!D:D)) | O32: =IF(M32="","",P32/M32) | U32: =IF(M32="","",_xlfn.XLOOKUP(I32,资产分类大全!C:C,资产分类大全!F:F,0)) | V32: =IF(I32<>"",IF(M32<U32,"不足","充足"),"")
A33: =IF(B33="","",ROW()-1) | C33: =IF(B33="","",_xlfn.XLOOKUP(I33,资产分类大全!C:C,资产分类大全!D:D)) | O33: =IF(M33="","",P33/M33) | U33: =IF(M33="","",_xlfn.XLOOKUP(I33,资产分类大全!C:C,资产分类大全!F:F,0)) | V33: =IF(I33<>"",IF(M33<U33,"不足","充足"),"")
A34: =IF(B34="","",ROW()-1) | C34: =IF(B34="","",_xlfn.XLOOKUP(I34,资产分类大全!C:C,资产分类大全!D:D)) | O34: =IF(M34="","",P34/M34) | U34: =IF(M34="","",_xlfn.XLOOKUP(I34,资产分类大全!C:C,资产分类大全!F:F,0)) | V34: =IF(I34<>"",IF(M34<U34,"不足","充足"),"")
A35: =IF(B35="","",ROW()-1) | C35: =IF(B35="","",_xlfn.XLOOKUP(I35,资产分类大全!C:C,资产分类大全!D:D)) | O35: =IF(M35="","",P35/M35) | U35: =IF(M35="","",_xlfn.XLOOKUP(I35,资产分类大全!C:C,资产分类大全!F:F,0)) | V35: =IF(I35<>"",IF(M35<U35,"不足","充足"),"")
A36: =IF(B36="","",ROW()-1) | C36: =IF(B36="","",_xlfn.XLOOKUP(I36,资产分类大全!C:C,资产分类大全!D:D)) | O36: =IF(M36="","",P36/M36) | U36: =IF(M36="","",_xlfn.XLOOKUP(I36,资产分类大全!C:C,资产分类大全!F:F,0)) | V36: =IF(I36<>"",IF(M36<U36,"不足","充足"),"")
... A100: =IF(B100="","",ROW()-1) | C100: =IF(B100="","",_xlfn.XLOOKUP(I100,资产分类大全!C:C,资产分类大全!D:D)) | O100: =IF(M100="","",P100/M100) | U100: =IF(M100="","",_xlfn.XLOOKUP(I100,资产分类大全!C:C,资产分类大全!F:F,0)) | V100: =IF(I100<>"",IF(M100<U100,"不足","充足"),"")
C101: =IF(B101="","",_xlfn.XLOOKUP(I101,资产分类大全!C:C,资产分类大全!D:D)) | U101: =IF(M101="","",_xlfn.XLOOKUP(I101,资产分类大全!C:C,资产分类大全!F:F,0))
C102: =IF(B102="","",_xlfn.XLOOKUP(I102,资产分类大全!C:C,资产分类大全!D:D)) | U102: =IF(M102="","",_xlfn.XLOOKUP(I102,资产分类大全!C:C,资产分类大全!F:F,0))
C103: =IF(B103="","",_xlfn.XLOOKUP(I103,资产分类大全!C:C,资产分类大全!D:D)) | U103: =IF(M103="","",_xlfn.XLOOKUP(I103,资产分类大全!C:C,资产分类大全!F:F,0))
C104: =IF(B104="","",_xlfn.XLOOKUP(I104,资产分类大全!C:C,资产分类大全!D:D)) | U104: =IF(M104="","",_xlfn.XLOOKUP(I104,资产分类大全!C:C,资产分类大全!F:F,0))
C105: =IF(B105="","",_xlfn.XLOOKUP(I105,资产分类大全!C:C,资产分类大全!D:D)) | U105: =IF(M105="","",_xlfn.XLOOKUP(I105,资产分类大全!C:C,资产分类大全!F:F,0))
C106: =IF(B106="","",_xlfn.XLOOKUP(I106,资产分类大全!C:C,资产分类大全!D:D)) | U106: =IF(M106="","",_xlfn.XLOOKUP(I106,资产分类大全!C:C,资产分类大全!F:F,0))
C107: =IF(B107="","",_xlfn.XLOOKUP(I107,资产分类大全!C:C,资产分类大全!D:D)) | U107: =IF(M107="","",_xlfn.XLOOKUP(I107,资产分类大全!C:C,资产分类大全!F:F,0))
...

Sheet 采购计划表
A1: 入库日期 | B1: 分公司 | C1: 资产编号 | D1: 物品名称 | E1: 规格型号 | F1: 图片 | G1: 供应商 | H1: 入库数量 | I1: 单价 | J1: 总金额 | K1: 需求部门 | L1: 采购经办人 | M1: 备注
A2: 45200 | B2: xx分公司 | D2: 笔记本电脑 | E2: Dell XPS 13 | H2: 5 | I2: 8000 | J2: 40000 | L2: 赵六 | M2: 批量采购
A3: 6 | H3: 是 | K3: =IF(B3="","",L3/J3)
A4: 7 | H4: 是 | K4: =IF(B4="","",L4/J4)
A5: 8 | H5: 是 | K5: =IF(B5="","",L5/J5)
A6: 9 | H6: 是 | K6: =IF(B6="","",L6/J6)
A7: 10 | H7: 是 | K7: =IF(B7="","",L7/J7)
A8: 11 | H8: 是 | K8: =IF(B8="","",L8/J8)
A9: 12 | H9: 是 | K9: =IF(B9="","",L9/J9)
A10: 13 | H10: 是 | K10: =IF(B10="","",L10/J10)
A11: 14 | H11: 是 | K11: =IF(B11="","",L11/J11)
A12: 15 | H12: 是 | K12: =IF(B12="","",L12/J12)
H13: 是 | K13: =IF(B13="","",L13/J13)
H14: 是 | K14: =IF(B14="","",L14/J14)
H15: 是 | K15: =IF(B15="","",L15/J15)
H16: 是 | K16: =IF(B16="","",L16/J16)
H17: 是
H18: 是
H19: 是
H20: 是
H21: 是
H22: 是
H23: 是
H24: 是
H25: 是
H26: 是
H27: 是
H28: 是

Sheet 物品领用登记表
A1: 分公司 | B1: 日期 | C1: 领用物品 | D1: 领用数量 | E1: 用途 | F1: 领用部门 | G1: 部门累计领用 | H1: 当前库存 | I1: 是否核对 | J1: 备注
H2: =IFERROR(VLOOKUP(C2,#REF!,4,FALSE),"") | I2: ☑
G3: =IF(B3="","",SUMIFS($D$2:D3,$F$2:F3,F3,$C$2:C3,C3)) | H3: =IFERROR(VLOOKUP(C3,#REF!,4,FALSE),"") | I3: ☑
G4: =IF(B4="","",SUMIFS($D$2:D4,$F$2:F4,F4,$C$2:C4,C4)) | H4: =IFERROR(VLOOKUP(C4,#REF!,4,FALSE),"") | I4: ☑
G5: =IF(B5="","",SUMIFS($D$2:D5,$F$2:F5,F5,$C$2:C5,C5)) | H5: =IFERROR(VLOOKUP(C5,#REF!,4,FALSE),"") | I5: □
G6: =IF(B6="","",SUMIFS($D$2:D6,$F$2:F6,F6,$C$2:C6,C6)) | H6: =IFERROR(VLOOKUP(C6,#REF!,4,FALSE),"") | I6: □
G7: =IF(B7="","",SUMIFS($D$2:D7,$F$2:F7,F7,$C$2:C7,C7)) | H7: =IFERROR(VLOOKUP(C7,#REF!,4,FALSE),"") | I7: □
G8: =IF(B8="","",SUMIFS($D$2:D8,$F$2:F8,F8,$C$2:C8,C8)) | H8: =IFERROR(VLOOKUP(C8,#REF!,4,FALSE),"") | I8: □
G9: =IF(B9="","",SUMIFS($D$2:D9,$F$2:F9,F9,$C$2:C9,C9)) | H9: =IFERROR(VLOOKUP(C9,#REF!,4,FALSE),"") | I9: □
G10: =IF(B10="","",SUMIFS($D$2:D10,$F$2:F10,F10,$C$2:C10,C10)) | H10: =IFERROR(VLOOKUP(C10,#REF!,4,FALSE),"") | I10: □
G11: =IF(B11="","",SUMIFS($D$2:D11,$F$2:F11,F11,$C$2:C11,C11)) | H11: =IFERROR(VLOOKUP(C11,#REF!,4,FALSE),"") | I11: □
G12: =IF(B12="","",SUMIFS($D$2:D12,$F$2:F12,F12,$C$2:C12,C12)) | H12: =IFERROR(VLOOKUP(C12,#REF!,4,FALSE),"") | I12: □
G13: =IF(B13="","",SUMIFS($D$2:D13,$F$2:F13,F13,$C$2:C13,C13)) | H13: =IFERROR(VLOOKUP(C13,#REF!,4,FALSE),"") | I13: □
G14: =IF(B14="","",SUMIFS($D$2:D14,$F$2:F14,F14,$C$2:C14,C14)) | H14: =IFERROR(VLOOKUP(C14,#REF!,4,FALSE),"") | I14: □
... G11079: =IF(B11079="","",SUMIFS($D$2:D11079,$F$2:F11079,F11079,$C$2:C11079,C11079)) | H11079: =IFERROR(VLOOKUP(C11079,#REF!,4,FALSE),"") | I11079: □

Sheet 调拨表格
A1: 调拨日期 | B1: 分公司(调出) | C1: 调出部门 | D1: 调入分公司 | E1: 调入部门 | F1: 资产编号 | G1: 资产名称 | H1: 规格型号 | I1: 调拨数量 | J1: 调拨原因 | K1: 调出负责人 | L1: 调入负责人 | M1: 备注
A2: 45209 | B2: xx分公司 | C2: XX部 | D2: yy分公司 | E2: 销售部 | G2: 笔记本电脑 | H2: Dell XPS 13 | I2: 1 | J2: 人员调动 | K2: 张三 | L2: 王七

Sheet 资产分类大全
A1: 资产类目 | B1: 物品分类 | C1: 资产名称 | D1: 资产编号 | E1: 计量单位 | F1: 警戒线 | G1: 备注 | I1: 分公司
A2: 固定资产类 | B2: 办公设备 | C2: 平板电脑 | D2: A-a00001 | E2: 个 | F2: 1 | I2: 轮空
A3: 固定资产类 | B3: 办公设备 | C3: 打印机 | D3: A-a00002 | E3: 个 | F3: 1 | I3: 流量中心
A4: 固定资产类 | B4: 办公设备 | C4: 复印机 | D4: A-a00003 | E4: 个 | F4: 1 | I4: 集团总部
A5: 固定资产类 | B5: 办公设备 | C5: 扫描仪 | D5: A-a00004 | E5: 个 | F5: 1 | I5: 1分
A6: 固定资产类 | B6: 办公设备 | C6: 碎纸机 | D6: A-a00005 | E6: 个 | F6: 1 | I6: 2分
A7: 固定资产类 | B7: 办公设备 | C7: 考勤机 | D7: A-a00006 | E7: 个 | F7: 1 | I7: 3分
A8: 固定资产类 | B8: 办公设备 | C8: 工作手机 | D8: A-a00007 | E8: 个 | F8: 5 | I8: 5分
A9: 固定资产类 | B9: 办公设备 | C9: 笔记本电脑 | D9: A-a00008 | E9: 个 | F9: 1 | I9: 6分（无锡）
A10: 固定资产类 | B10: 办公设备 | C10: 鼠标 | D10: A-a00009 | E10: 个 | F10: 2 | I10: 7分
A11: 固定资产类 | B11: 办公设备 | C11: 键盘 | D11: A-a00010 | E11: 个 | F11: 2 | I11: 10分
A12: 固定资产类 | B12: 办公设备 | C12: 电脑（一体机） | D12: A-a00011 | E12: 个 | F12: 5 | I12: 12分（温州）
A13: 固定资产类 | B13: 办公设备 | C13: 电脑（台式） | D13: A-a00012 | E13: 个 | F13: 1 | I13: 15分（金华）
... A58: 固定资产类 | B58: 家具设施 | C58: 白板 | D58: A-c00019 | E58: 套 | F58: 1 | I58: 贵阳分公司
A59: 固定资产类 | B59: 家具设施 | C59: 茶桌 | D59: A-c00020 | E59: 套 | F59: 1
A60: 固定资产类 | B60: 家具设施 | C60: 茶桌椅 | D60: A-c00021 | E60: 套 | F60: 1
A61: 固定资产类 | B61: 家具设施 | C61: 电茶炉 | D61: A-c00022 | E61: 套 | F61: 1
A62: 固定资产类 | B62: 家具设施 | C62: 挂画 | D62: A-c00023 | E62: 个 | F62: 1
A63: 固定资产类 | B63: 家具设施 | C63: 文化墙 | D63: A-c00024 | E63: 个 | F63: 1
A64: 固定资产类 | B64: 家具设施 | C64: 渠道台 | D64: A-c00025 | E64: 个 | F64: 1
A65: 固定资产类 | B65: 家具设施 | C65: 前台 | D65: A-c00026 | E65: 个 | F65: 1
A66: 固定资产类 | B66: 家具设施 | C66: 老板桌 | D66: A-c00027 | E66: 个 | F66: 1
A67: 固定资产类 | B67: 家具设施 | C67: 老板椅 | D67: A-c00028 | E67: 个 | F67: 1
A68: 固定资产类 | B68: 家具设施 | C68: 塑料椅 | D68: A-c00029 | E68: 个 | F68: 1
A69: 固定资产类 | B69: 家具设施 | C69: 地毯 | D69: A-c00030 | E69: 个 | F69: 1
A70: 固定资产类 | B70: 家具设施 | C70: 门锁 | D70: A-c00031 | E70: 个 | F70: 1
... A381: 其他资产 | B381: 维修备件 | C381: 铲子 | D381: F-b00008 | E381: 个 | F381: 1
